Workbook

Sheet ref
C3: MVPF - BF
D4: Ref completa | E4: Acesso em
B5: 1 | C5: Impacto sobre a mortalidade infatil | D5: SHEI, Amie. Brazil’s conditional cash transfer program associated with declines in infant mortality rates. Health Affairs, v. 32, n. 7, p. 1274-1281, 2013. | E5: https://www.healthaffairs.org/doi/10.1377/hlthaff.2012.0827
B6: 2 | C6: Valor estatístico de uma vida | D6: PEREIRA, Rafael Mesquita; ALMEIDA, Alexandre Nunes de; OLIVEIRA, Cristiano Aguiar de. O valor estatístico de uma vida: estimativas para o Brasil. Estudos Econômicos (São Paulo), v. 50, p. 227-259, 2020. | E6: https://www.revistas.usp.br/ee/article/view/160043/161629
B7: 3 | C7: Impacto sobre o Drop Out de crianças cujos pais receberam BF | D7: GLEWWE, Paul; KASSOUF, Ana Lucia. The impact of the Bolsa Escola/Familia conditional cash transfer program on enrollment, dropout rates and grade promotion in Brazil. Journal of development Economics, v. 97, n. 2, p. 505-517, 2012. | E7: https://pdf.sciencedirectassets.com/271688/1-s2.0-S0304387811X0007X/1-s2.0-S0304387811000538/main.pdf?X-Amz-Security-Token=IQoJb3JpZ2luX2VjEOD%2F%2F%2F%2F%2F%2F%2F%2F%2F%2FwEaCXVzLWVhc3QtMSJIMEYCIQCVByvlata7ghiFij5xFh1BS4Vtjzj5SVb2Qw82rmx4GAIhAMm5hGEjUFFe2pTVPbUBjnhKA91%2B5vrZwFNoUiVbO8plKrIFCBgQBRoMMDU5MDAzNTQ2ODY1Igy4mhZrFuLK2icLHpcqjwV0hFVy%2FHQrt7u8M1oeDhVLTLZZkMVI%2BoyBHN2IolUcQHLke3H4xlL%2B9X2q2b8w0uCkHjYFvdN%2BZutX8vH41rexLMqb4gpeYvk6BmQ%2FjmuLzMvhyiYQmDPYtK2MGjw643zowFM3shO1ZajMN3i5wrJEbtG2qscJ5zdrGf1zLiBmQl8mVWw15K9rSNNFqVyLeavOK%2B8oRplQz%2B1rVjyNXNDx0KJERB2%2BR3cbp41%2F3QCRW6PRc1tYnHOcvAChH6h4goGHne1E8u6%2B6Pcxb0UWFrWztIr2hykMdRQuI13%2B4IWuiGUA12xQo%2FJaZXyskK3k%2BfzwWXECce2yScRt8yUYsaM1fuJGNK%2F1kntJYy7JBa8OaN%2Bf5jtDd1P4SZEGCk2%2BoMrF5UzhyHQRludUN8252GYDgJw28xsqHYZndR5pj4F4z5HK6vYhr%2FBTKSY2S0ZL%2BRf728FHjA5ovPnKCmJI2flIk0ZtZXdIdGqIMSggVUGvuM8sMhIEJ7nvF5DbOxO0DkPgzhjWbczsgoIRL9OhhFQAXsxGmy8J5FTT8fnzoPOSg7czd61ur7R%2BIAXKT140Iom2twwnfqdVtRPe7tq6gyn1qLwWC6abAgTeCuN8McNjy686VKuwXicIIw0TwrcJEyzCffa%2BdDcoxnVQjLFm8Rjdv2B3PKxasp4LIQBA5UFZ%2FZigKQtZlwiaIEKU%2F%2FVu7Zac2YFAtDrhX%2B%2FNNMT4N3yCOFNIruXdZS1gK8Y6%2BYH0nYKfnfPh%2BkDJu9mhaM9qof7HUSnsQZCyuiiw%2FquSQNxG7I2%2Fs11IKuIpFG%2FeKGjYHvZ%2B%2FhWPOq%2BTG79am7sZ%2Fx0pcCY5TQ7K5%2BpcGngETAtlDHizSopy036HgKpFoytYMI7TiaoGOrABg5VslTaZEyElMir7L5dtRle7XzlB4stFzanv3OZbIC%2FfFhWqxJlWGBUVoiHaLCKDDX%2BHMIpuBnO7MMz1sGrdXQjv9TZbYAT%2FkVJmcBfbVfS6Zw5%2BnVUTslOKS9DjXCY5qLycVjVnAAPD6ovJqywmsbcG68jnHAFaDrefSTWPTuV2VD9hmZQRyw8f2HEjOQUsUk4snKyTLgXXWmtJyso2OJylJ5OJ8a22SZ1k3NZu5d0%3D&X-Amz-Algorithm=AWS4-HMAC-SHA256&X-Amz-Date=20231101T162406Z&X-Amz-SignedHeaders=host&X-Amz-Expires=300&X-Amz-Credential=ASIAQ3PHCVTY4JVSQSTW%2F20231101%2Fus-east-1%2Fs3%2Faws4_request&X-Amz-Signature=d3f036fe29ba9280daaf4f894ffa13b9949f4812c232371a39657a1aedbff2f2&hash=a4cca87138d55f1c5ac26395d441c53fc49171aa2ff68095e20f59261948aec7&host=68042c943591013ac2b2430a89b270f6af2c76d8dfd086a07176afe7c76c2c61&pii=S0304387811000538&tid=spdf-2f3224fb-b9ec-4ac3-a9a8-e19c8d90139c&sid=e6cfd1268f9cc44ad16b68813ebb0ae522b4gxrqa&type=client&tsoh=d3d3LnNjaWVuY2VkaXJlY3QuY29t&ua=18145c540050500352055a&rr=81f57c6e4982030d&cc=br
B8: 4 | C8: Impacto do ganho de escolaridade na renda | D8: Boletim regional – janeiro de 2019. Disponível em: <https://www.bcb.gov.br/publicacoes/boletimregional/201901>. Acesso em: 7 nov. 2024. | E8: https://www.bcb.gov.br/publicacoes/boletimregional/201901
B9: 5 | C9: Impacto sobre geração de empregos formais (obtem custo implícito por emprego formal) | D9: GERARD, François; NARITOMI, Joana; SILVA, Joana. Cash transfers and formal labor markets: Evidence from Brazil. 2021. | E9: https://www.dropbox.com/s/fgb3wt9r1uzggit/CT_GerardNaritomiSilva.pdf?dl=0

Sheet WTP
A3: Obs | B3: Fonte | C3: WTP
C4: =costs!A13 -> Valor do benefício médio anual | D4: =costs!B13 -> 1223.16
C5: Valor devido a alterações comportamentais (fornece disposição de pagar mínima) | D5: =D4 -> 1223.16
C7: =costs!A7 -> Numero de individuos no BF | D7: =costs!B7 -> 52237520
C8: Número de pessoas (1% do PBF) | D8: =D7*0.01 -> 522375.2
C9: Nascimentos (2010) | D9: 2747373
A10: Não reporta sd | B10: SHEI, Amie. Brazil’s conditional cash transfer program associated with declines in infant mortality rates. Health Affairs, v. 32, n. 7, p. 1274-1281, 2013. | C10: ATT Bolsa Família | D10: 0.093
A11: Não reporta sd | B11: PEREIRA, Rafael Mesquita; ALMEIDA, Alexandre Nunes de; OLIVEIRA, Cristiano Aguiar de. O valor estatístico de uma vida: estimativas para o Brasil. Estudos Econômicos (São Paulo), v. 50, p. 227-259, 2020. | C11: VSL (value of a statistical life ) de R$3,294 milhão (em reais de 2015) | D11: 3294000
C12: VSL (em reais de 2010) - 1.44 é o Índice de Correção para o período | D12: =D11/1.4442715 -> 2280734.6
C13: Mortes Infantis - menores de 1 ano (2010) | D13: 31429
C14: Mortalidade sem o programa | D14: =D13/(1-0.09) -> 34537.363
C15: Vidas Salvas | D15: =D14-D13 -> 3108.3626
C16: ganho econômico por beneficiário adicionado | D16: =(D15*D12)/D7 -> 135.71376
C17: ganho econômico por família adicionada | D17: =D16*costs!B8 -> 529.28366
C18: Disposição a pagar dos pais | D18: =(D17+D5)/$D$5 -> 1.4327183
A20: Estimada com base no impacto do BF nas taxas de "Drop Out", e do impacto de um ano a mais de escolaridade na renda futura (ao lado) | B20: Estimativas Próprias | C20: Aumento esperado na renda futura dos filhos de participantes do BF | D20: =H31 -> 0.049276772 | G20: Calculo de Ganho de produtividade
C21: alíquota de impostos | D21: 0.22 | F21: Fonte: | H21: Séries
C22: Rendimento médio por integrante beneficiario do BF por ano - sem o BF | D22: =12*costs!B9 -> 646.8 | H22: 1 | I22: 2 | J22: 3 | K22: 4 | L22: 5 | M22: 6 | N22: 7 | O22: 8 | P22: 9 | Q22: TOTAL
C23: imposto - sem BF | D23: =D21*D22 -> 142.296 | G23: Taxa de "Drop Out" | H23: 0.004 | I23: 0.003 | J23: 0.003 | K23: 0.003 | L23: 0.004 | M23: 0.011 | N23: 0.013 | O23: 0.016 | P23: 0.016
C24: Rendimento - sem BF - liquido | D24: =D22-D23 -> 504.504 | F24: GLEWWE, Paul; KASSOUF, Ana Lucia. The impact of the Bolsa Escola/Familia conditional cash transfer program on enrollment, dropout rates and grade promotion in Brazil. Journal of development Economics, v. 97, n. 2, p. 505-517, 2012. | G24: Redução na Taxa de "Drop Out" | H24: =3*(0.00299 + 0.00245) -> 0.01632 | I24: =3*(0.00299 + 0.00245) -> 0.01632 | J24: =3*(0.00299 + 0.00245) -> 0.01632 | K24: =3*(0.00299 + 0.00245) -> 0.01632 | L24: =3*(0.00299 + 0.00245) -> 0.01632 | M24: =3*(0.00264 + 0.00111 + 0.00177) -> 0.01656 | N24: =3*(0.00264 + 0.00111 + 0.00177) -> 0.01656 | O24: =3*(0.00264 + 0.00111 + 0.00177) -> 0.01656 | P24: =3*(0.00264 + 0.00111 + 0.00177) -> 0.01656
C25: Rendimento médio - considerando aumento de produtividade | D25: =D22*(1+D20) -> 678.67222 | G25: Taxa de "Drop Out" sem Bolsa | H25: =H24+H23 -> 0.02032 | I25: =I24+I23 -> 0.01932 | J25: =J24+J23 -> 0.01932 | K25: =K24+K23 -> 0.01932 | L25: =L24+L23 -> 0.02032 | M25: =M24+M23 -> 0.02756 | N25: =N24+N23 -> 0.02956 | O25: =O24+O23 -> 0.03256 | P25: =P24+P23 -> 0.03256
C26: imposto - com BF | D26: =D25*D21 -> 149.30789
C27: Rendimento - com BF - liquido | D27: =D25-D26 -> 529.36433 | G27: Prob de Continuar | H27: =(1-H23) -> 0.996 | I27: =(1-I23) -> 0.997 | J27: =(1-J23) -> 0.997 | K27: =(1-K23) -> 0.997 | L27: =(1-L23) -> 0.996 | M27: =(1-M23) -> 0.989 | N27: =(1-N23) -> 0.987 | O27: =(1-O23) -> 0.984 | P27: =(1-P23) -> 0.984 | Q27: =PRODUCT(H27:P27) -> 0.92919699
C28: Anos de trabalho | D28: 40 | G28: Prob de Continuar (s/bolsa) | H28: =(1-H25) -> 0.97968 | I28: =(1-I25) -> 0.98068 | J28: =(1-J25) -> 0.98068 | K28: =(1-K25) -> 0.98068 | L28: =(1-L25) -> 0.97968 | M28: =(1-M25) -> 0.97244 | N28: =(1-N25) -> 0.97044 | O28: =(1-O25) -> 0.96744 | P28: =(1-P25) -> 0.96744 | Q28: =PRODUCT(H28:P28) -> 0.79952127
C29: Anos de Estudo (de custo) | D29: 9
C30: Taxa de desconto | D30: 0.03 | F30: Boletim regional – janeiro de 2019. Disponível em: <https://www.bcb.gov.br/publicacoes/boletimregional/201901>. Acesso em: 7 nov. 2024. | G30: Ganho de Renda por Término do EF (Boletim Regional do BC - janeiro de 2019) | H30: 0.38 | Q30: =Q27-Q28 -> 0.12967572
G31: Ganho de renda por ganho de escolaridade (38% por completar o fundamental): | H31: =H30*(Q27-Q28) -> 0.049276772
C32: Ganho líquido do "filho" do bolsa famolia (aumento na renda para filho de participante, que teve retorno a educação e aumento de salário) | D32: =D27-D24 -> 24.860328
F33: Tx. De Desconto | G33: Cálculo do VPL
F34: 0.03 | H34: Ganhos (Educação) | I34: Custo do Programa
C35: VPL do ganho por filho ao longo de 40 anos | D35: =SUM(H44:H83) -> 453.62677 | F35: Crescimento | G35: =0 -> 0 | H35: 0 | I35: =$D$5/(1+$F$34)^G35 -> 1223.16
C36: Custo | D36: =SUM(I35:I43) -> 9809.3667 | F36: 0 | G36: =G35+1 -> 1 | H36: 0 | I36: =$D$5/(1+$F$34)^G36 -> 1187.534
C37: Nº de filhos beneficiado pelo ganho de produtividade | D37: 2 | G37: =G36+1 -> 2 | H37: 0 | I37: =$D$5/(1+$F$34)^G37 -> 1152.9456
C38: Disposição a pagar dos filhos | D38: =D37*(D35/$D$36) -> 0.092488493 | G38: =G37+1 -> 3 | H38: 0 | I38: =$D$5/(1+$F$34)^G38 -> 1119.3647
G39: =G38+1 -> 4 | H39: 0 | I39: =$D$5/(1+$F$34)^G39 -> 1086.7618
G40: =G39+1 -> 5 | H40: 0 | I40: =$D$5/(1+$F$34)^G40 -> 1055.1086
G41: =G40+1 -> 6 | H41: 0 | I41: =$D$5/(1+$F$34)^G41 -> 1024.3772
G42: =G41+1 -> 7 | H42: 0 | I42: =$D$5/(1+$F$34)^G42 -> 994.54101
G43: 8 | H43: 0 | I43: =$D$5/(1+$F$34)^G43 -> 965.5738
G44: =G43+1 -> 9 | H44: =$D$32*((1+$F$36)/(1+$F$34))^G44 -> 19.053372
...

Sheet costs
A1: Fonte: | B1: GERARD, François; NARITOMI, Joana; SILVA, Joana. Cash transfers and formal labor markets: Evidence from Brazil. 2021. | C1: https://www.dropbox.com/s/fgb3wt9r1uzggit/CT_GerardNaritomiSilva.pdf?dl=0
A2: TABLE 1: PBF BENEFICIARIES AND FORMAL EMPLOYMENT | C2: impact of PBF on local formal labor markets
A3: Cadastro único - agosto de 2010 | C3: Desvio Padrão | D3: ref
A5: Numero de familias | B5: 20564520 | D5: Pagina 12
A6: Numero de individuos | B6: 72765336 | D6: Pagina 12
A7: Numero de individuos no BF | B7: 52237520 | D7: Pagina 12
A8: Tamanho médio da família (beneficiarios BF) | B8: 3.9 | D8: Pagina 12
A9: Renda per capita média da família (beneficiarios BF) | B9: 53.9 | D9: Pagina 12
A10: Renda Total média da família sem BF (beneficiarios BF) | B10: 206.3 | D10: Pagina 12
A11: Benefício médio por família | B11: 101.93 | D11: Pagina 12
A12: Meses | B12: 12
A13: Valor do benefício médio anual | B13: =B11*B12 -> 1223.16
A14: Renda média anual familiar - sem BF | B14: =B10*B12 -> 2475.6
A15: Renda média anual familiar - com BF | B15: =B14+B13 -> 3698.76
A16: Renda média anual per capita - sem BF | B16: =B9*B12 -> 646.8
A17: Aumento de 13,6% nos pagamentos totais do bolsa família gera aumento de 2% no emprego formal- privado | B17: 0.02 | C17: 0.007 | D17: Página 23 - table 3 | E17: diff- in-diff
A18: Aumento de 13,6% nos pagamentos do bolsa família gera aumento de 2,7% nos impostos pagos | B18: 0.027
A19: Aumento de 1% nos pagamentos do bolsa família gera aumento de 0,20% nos impostos pagos | B19: =2.7/13.6 -> 0.19852941
A20: Taxa de impostos e transferências | B20: 0.22
B23: =728.3*12 -> 8739.6
A25: Custo implícito por emprego formal (anual)- o número de empregos formais adicionais dividido pelo aumento nos pagamentos do PBF (Programa Bolsa Família) - (U$ 2016) | B25: =112/B17 -> 5600
A26: taxa de cambio em 2016 | B26: 3.5
A27: taxa de inflação média (entre 2010 e 2016) | B27: 0.06
A28: tempo entre 2010-2016 | B28: 6
A29: Custo implícito por emprego formal (anual) - R$ 2010 | B29: =(B25*B26)/(1+B27)^B28 -> 13817.227
A30: Beneficio final do BF em termos de emprego (custo anual do programa por família / beneficio em termos de emprego gerado pelo BF) | B30: =B13/B29 -> 0.088524277
A31: Salário Médio Anual Mercado Formal em 2010 (CEMPRE, 2010) | B31: =1650.3*12 -> 19803.6
A32: Aumento da renda devido a uma família beneficiária a mais | B32: =B31*B30 -> 1753.0994
A33: Taxa de impostos e transferências | B33: 0.22
A34: Externalidade fiscal devido ao aumento na arrecadação tributária | B34: =B32*B33 -> 385.68186
A35: Externalidade fiscal devido ao aumento na arrecadação tributária - via aumento de renda dos filhos | B35: =PRODUCT(WTP!D38,WTP!D21,WTP!D5) -> 24.88821
A36: Índice de gestão descentralizada do Bolsa Família e do CadÚnico (IGD/PBF) - custo por cadastro valido (https://aprece.org.br/noticia/indice-de-gestao-descentralizada-do-bolsa-familia-e-do-cadunico-teve-valor-reajustado/#:~:text=A%20Portaria%20887%2F2023%2C%20publicada,a%20ser%20repassado%20aos%20municípios) | B36: 3.25
A37: Liquido | B37: =B34+B35-B36 -> 407.32007
A38: Externalidade fiscal de reais por cada R$1 em BF | B38: =(B13-B37)/B13 -> 0.66699363
B39: =1-B38 -> 0.33300637

Sheet MVPF
C3: MVPF
C4: Custo líquido do governo (em % do benefício) | D4: =costs!B38 -> 0.66699363
C5: Disposição a pagar dos pais | D5: =WTP!D18 -> 1.4327183
C6: MVPF sem disposição a pagar dos filhos | D6: =D5/$D$4 -> 2.1480239
C8: SOMA (Disposição a pagar dos filhos + Disposição a pagar dos pais) | D8: =D5+WTP!D38 -> 1.5252068
C9: MVPF - PBF | D9: =D8/$D$4 -> 2.2866886
C11: Valoração Direta | D11: Valoração Vida Infantil | E11: Valoração Ganho de Produtividade | F11: Subtotal
C12: 1 | D12: =D5-1 -> 0.43271826 | E12: =D8-D5 -> 0.092488493 | F12: =E12+D12+C12 -> 1.5252068
